Workbook

Sheet Read Me
A1: Agent Skills With Anthropic — Assessment Bundle
A2: Companion workbook to the course notes, deck and interactive study app. Sourced from the DeepLearning.AI course transcripts, the published Agent Skills specification and Anthropic's documentation.
A4: Sheet | B4: What it contains | C4: Primary use
A5: Quiz Bank | B5: 65 assessment items: multiple choice, true or false, short answer and applied scenarios. Includes the correct answer and a rationale for every item. | C5: Trainer reference and self-test
A6: Flashcards | B6: 98 prompt-and-answer pairs for spaced rehearsal, tagged by module and theme. | C6: Daily recall drill
A7: Spec Cheat Sheet | B7: Every hard limit, path, directory name and API string drawn from the 14 modules. | C7: Look-up during build work
A8: Glossary | B8: 24 terms defined in one line each. | C8: Onboarding a new team member
A9: Score Tracker | B9: Enter 1 for correct and 0 for missed against each item. Totals and per-module breakdowns calculate automatically. | C9: Track a cohort or your own retakes
A12: How to use the score tracker
A13: Instruction
A14: Edit only the Score column (column F) on the Score Tracker sheet. Every other cell is a formula or a label.
A15: Enter 1 for a correct answer and 0 for a missed one. Leave the cell empty for an item you skipped.
A16: Example: for item Q01, if the learner answered correctly, F5 = 1. If the learner missed it, F5 = 0.
A17: Input cells are shaded pale blue. Totals recalculate as you type, and attempted items exclude blanks.
A18: Short-answer and applied items are self-graded against the model answer on the Quiz Bank sheet.
A21: Difficulty scale
A22: Level | B22: Meaning
A23: 1 | B23: Recall — a named fact, limit or path
A24: 2 | B24: Apply — use the concept on a described situation
A25: 3 | B25: Judgement — choose between primitives, or defend a design
A28: Point-in-time note: API beta headers, code execution tool version strings and subagent skill-injection behaviour were accurate to the course recording and to documentation reviewed in September 2026. Verify these against current documentation before teaching them as fact.

Sheet Quiz Bank
A1: Quiz Bank
A2: Fifty items across 14 modules. Options are blank for true or false, short answer and applied items.
A4: ID | B4: Module | C4: Module title | D4: Type | E4: Difficulty | F4: Question | G4: Option A | H4: Option B | I4: Option C | J4: Option D | K4: Correct answer | L4: Rationale
A5: Q01 | B5: 02 | C5: Anatomy of a Skill and the Open Standard | D5: mcq | E5: 1 | F5: Which fields are REQUIRED in a skill's YAML frontmatter? | G5: name and version | H5: name and description | I5: description and allowed-tools | J5: name, description and license | K5: name and description | L5: Only `name` and `description` are required by the specification. `license`, `compatibility`, `metadata` and `allowed-tools` are optional, and `allowed-tools` is still experimental.
A6: Q02 | B6: 02 | C6: Anatomy of a Skill and the Open Standard | D6: mcq | E6: 1 | F6: What is the maximum length of a skill's `name`? | G6: 32 characters | H6: 64 characters | I6: 128 characters | J6: 1,024 characters | K6: 64 characters | L6: `name` is capped at 64 characters; `description` at 1,024; `compatibility` at 500.
A7: Q03 | B7: 03 | C7: Progressive Disclosure and Context as a Public Good | D7: mcq | E7: 1 | F7: At session start, what is loaded into context for every installed skill? | G7: The entire skill folder | H7: The SKILL.md body | I7: Only name and description | J7: Nothing until the skill is named by the user | K7: Only name and description | L7: Tier 1 of progressive disclosure is metadata only, roughly 100 tokens per skill. The body loads at tier 2, when the description matches.
A8: Q04 | B8: 03 | C8: Progressive Disclosure and Context as a Public Good | D8: mcq | E8: 2 | F8: Why is putting deterministic logic in `scripts/` cheaper than putting it in `references/`? | G8: Scripts are compressed before loading | H8: Script source is never tokenised — only its output enters context | I8: Reference files are always loaded at startup | J8: Scripts run on a separate model | K8: Script source is never tokenised — only its output enters context | L8: A 600-line script can cost a few dozen tokens of stdout. A reference file costs its full length the moment it is read.
A9: Q05 | B9: 05 | C9: Pre-Built Skills, the Marketplace and skill-creator | D9: mcq | E9: 1 | F9: Which set of skills is built into Claude.ai and cannot be toggled off? | G9: skill-creator and mcp-builder | H9: docx, pdf, pptx, xlsx | I9: brand-guidelines and canvas-design | J9: webapp-testing and frontend-design | K9: docx, pdf, pptx, xlsx | L9: The four document skills are built in and always available in Claude.ai/Desktop. Example skills are toggleable and off by default, except skill-creator.
A10: Q06 | B10: 05 | C10: Pre-Built Skills, the Marketplace and skill-creator | D10: mcq | E10: 1 | F10: Which example skill is enabled by default in Claude? | G10: mcp-builder | H10: skill-creator | I10: algorithmic-art | J10: webapp-testing | K10: skill-creator | L10: skill-creator is the documented exception to the example skills being off by default.
A11: Q07 | B11: 07 | C11: Skills with the Claude Messages API | D11: mcq | E11: 1 | F11: Which tool is a hard requirement for using skills on the Claude Messages API? | G11: The web search tool | H11: The code execution tool | I11: The computer use tool | J11: The text editor tool | K11: The code execution tool | L11: Skills need a filesystem and a shell. On the API those come from the code execution tool's container; without it the request fails with a 400.
A12: Q08 | B12: 07 | C12: Skills with the Claude Messages API | D12: mcq | E12: 1 | F12: Where do uploaded custom skills mount inside the API execution container? | G12: /home/claude/skills/ | H12: /skills/<skill-name>/ | I12: /mnt/skills/custom/ | J12: /tmp/skills/ | K12: /skills/<skill-name>/ | L12: Both custom and built-in skills are mounted under /skills/, which is why traces show `cat /skills/<name>/SKILL.md`.
A13: Q09 | B13: 07 | C13: Skills with the Claude Messages API | D13: mcq | E13: 2 | F13: A script inside your skill does `pip install statsmodels` at runtime and fails on the API. Why? | G13: pip is not installed in the container | H13: The container has no internet connection | I13: Skills are not allowed to run pip | J13: The package is blocked by policy | K13: The container has no internet connection | L13: The API sandbox has no network access, so every dependency must already be present. Claude.ai and Desktop containers do have network access, which is why the same script can pass there and fail on the API.
A14: Q10 | B14: 08 | C14: Skills in Claude Code, and Wiring Them to Subagents | D14: mcq | E14: 1 | F14: Where do project-scoped skills live in a Claude Code repository? | G14: .skills/<name>/SKILL.md | H14: .claude/skills/<name>/SKILL.md | I14: skills/<name>/skill.md | J14: ~/.claude/project-skills/ | K14: .claude/skills/<name>/SKILL.md | L14: Project skills go in `.claude/skills/`; personal skills in `~/.claude/skills/`.
A15: Q11 | B15: 08 | C15: Skills in Claude Code, and Wiring Them to Subagents | D15: mcq | E15: 2 | F15: You add a new skill folder to `.claude/skills/` and `/skills` does not list it. Most likely cause? | G15: The frontmatter is invalid | H15: Claude Code needs restarting to discover it | I15: The skill exceeds 500 lines | J15: Project skills must be registered in settings.json | K15: Claude Code needs restarting to discover it | L15: Skills are discovered at startup. Invalid frontmatter is the other candidate, but the restart is the documented and far more common cause.
A16: Q12 | B16: 09 | C16: Skills with the Claude Agent SDK | D16: mcq | E16: 2 | F16: In the Agent SDK you set `allowed_tools=["Skill", "Task", "Bash"]` and your skills still never load. What is missing? | G16: `skills="all"` in the options | H16: `setting_sources` including 'project' or 'user' | I16: The Read tool | J16: A beta header | K16: `setting_sources` including 'project' or 'user' | L16: Skills in the SDK need both the `Skill` tool AND `setting_sources` naming where to load from. Omitting `setting_sources` loads nothing, silently.
... A24: Q20 | B24: 10 | C24: Evaluating Skills Like Software | D24: mcq | E24: 3 | F24: Your skill scores 9/10 on your eval set. What does that alone tell you about the skill's value? | G24: It is production-ready | H24: Very little without a baseline run | I24: That its description is well tuned | J24: That it will generalise across models | K24: Very little without a baseline run | L24: Without running the same queries with the skill disabled, you have measured the model's competence rather than the skill's contribution. Value is the delta.
A25: Q21 | B25: 01 | C25: Why Skills: From Repeated Prompt to Packaged Asset | D25: tf | E25: 1 | F25: A skill uploaded in Claude.ai is automatically available through the Claude API. | G25: True | H25: False | K25: False | L25: Claude.ai/Desktop skills are a separate store from the API and Claude Code. The same folder must be installed in each.
A26: Q22 | B26: 08 | C26: Skills in Claude Code, and Wiring Them to Subagents | D26: tf | E26: 2 | F26: Subagents in Claude Code automatically inherit the skills available to the parent agent. | G26: True | H26: False | K26: False | L26: They do not inherit skills. Skills must be attached explicitly — and a skill attached to a subagent is injected in full at dispatch, with no further progressive disclosure.
A27: Q23 | B27: 03 | C27: Progressive Disclosure and Context as a Public Good | D27: tf | E27: 2 | F27: Progressive disclosure applies inside a dispatched subagent exactly as it does in the main agent. | G27: True | H27: False | K27: False | L27: For a skill preloaded onto a subagent, the entire SKILL.md is injected at startup. Budget for the full body, not the metadata.
A28: Q24 | B28: 11 | C28: Security, Trust and Governance | D28: tf | E28: 2 | F28: Instructions in a SKILL.md body can prevent an agent from writing files. | G28: True | H28: False | K28: False | L28: The body is advisory text to a model. Enforcement comes from tool allow-lists, permission hooks and sandbox configuration.
A29: Q25 | B29: 02 | C29: Anatomy of a Skill and the Open Standard | D29: tf | E29: 1 | F29: Unknown top-level frontmatter fields cause a skill to fail loading. | G29: True | H29: False | K29: False | L29: Unknown fields are ignored for forward compatibility. Invalid YAML, wrong casing and duplicate recognised keys DO stop it loading.
A30: Q26 | B30: 05 | C30: Pre-Built Skills, the Marketplace and skill-creator | D30: tf | E30: 1 | F30: Claude Code ships with the document skills already installed. | G30: True | H30: False | K30: False | L30: It ships with none of them. Install via the plugin marketplace, then restart.
A31: Q27 | B31: 05 | C31: Pre-Built Skills, the Marketplace and skill-creator | D31: tf | E31: 2 | F31: A perfectly matching description guarantees the skill will fire. | G31: True | H31: False | K31: False | L31: On a trivial one-step request the model answers directly rather than consulting a skill. Triggering is also stochastic across identical requests.
A32: Q28 | B32: 07 | C32: Skills with the Claude Messages API | D32: tf | E32: 2 | F32: Files uploaded through the Files API expire automatically after a short retention window. | G32: True | H32: False | K32: False | L32: They persist until explicitly deleted and count against your organisation's storage.
A33: Q29 | B33: 04 | C33: Skills vs Tools vs MCP vs Subagents vs Prompts | D33: tf | E33: 2 | F33: A subagent can spawn its own subagents to parallelise further. | G33: True | H33: False | K33: False | L33: Subagents have no Task tool. The topology stays a shallow tree by design.
A34: Q30 | B34: 09 | C34: Skills with the Claude Agent SDK | D34: tf | E34: 2 | F34: Listing a tool in a subagent's own tool list is sufficient for that subagent to use it. | G34: True | H34: False | K34: False | L34: The parent's `allowed_tools` must also include it, or the subagent is denied at runtime.
A35: Q31 | B35: 02 | C35: Anatomy of a Skill and the Open Standard | D35: tf | E35: 1 | F35: The folder name and the frontmatter `name` must match under the open specification. | G35: True | H35: False | K35: True | L35: The name must match the parent directory name, which is why renaming a folder without updating frontmatter breaks discovery.
A36: Q32 | B36: 12 | C36: Portability, Ecosystem and What Is Still Moving | D36: tf | E36: 2 | F36: `allowed-tools` is a reliable cross-host security control. | G36: True | H36: False | K36: False | L36: It is experimental: honoured in some hosts, silently ignored in others. Never use it as the enforcement layer.
A37: Q33 | B37: 03 | C37: Progressive Disclosure and Context as a Public Good | D37: short | E37: 1 | F37: Name the three tiers of progressive disclosure and what loads at each. | K37: 1) Metadata — name and description for every installed skill, always loaded (~100 tokens each). 2) Instructions — the full SKILL.md body, loaded when the description matches the request. 3) Resources — reference files, assets and scripts, loaded or executed only when the body directs it. | L37: This is the single most tested concept in the course; the cost profile of each tier drives every design decision downstream.
A38: Q34 | B38: 01 | C38: Why Skills: From Repeated Prompt to Packaged Asset | D38: short | E38: 2 | F38: Give the signature of content that belongs in `references/` rather than in the SKILL.md body, and an example from the course. | K38: Conditional plus bulky: material needed only in a minority of runs, and long enough to matter if it were always loaded. The course example is `references/budget_reallocation_rules.md` — most weekly runs never ask about reallocation, and the rule system is long. | L38: Unconditional reference files are just a slower long SKILL.md; the saving comes from the conditionality.
A39: Q35 | B39: 06 | C39: Authoring Practice: Descriptions, Degrees of Freedom, Structure | D39: short | E39: 2 | F39: Describe the three-part architecture used by the time-series skill and why each part sits where it does. | K39: Scripts for determinism (statistical tests in `diagnose.py` / `visualize.py`, so the same input produces the same numbers and only stdout costs tokens); SKILL.md for sequence (which script, in what order, what may be skipped and why, and the output tree); references for interpretation (`interpretation.md`, read only when the agent must explain what a result means). | L39: This is the most transplantable pattern in the course for any analytical workflow.
A40: Q36 | B40: 04 | C40: Skills vs Tools vs MCP vs Subagents vs Prompts | D40: short | E40: 2 | F40: Explain the difference between MCP and a skill using one concrete example. | K40: MCP provides connectivity — a BigQuery MCP server exposes tools to list tables, read a schema and run a query. The skill provides method — which table to query for weekly campaign performance, the date-range rules, the benchmarks to compare against, and the output format. MCP brings the tools; the skill knows what to do with them. | L40: The course's L3 demo is exactly this: the marketing skill was edited to name the MCP server and tool while its analysis and output sections stayed unchanged.
A41: Q37 | B41: 08 | C41: Skills in Claude Code, and Wiring Them to Subagents | D41: short | E41: 2 | F41: How do you decide whether a convention belongs in CLAUDE.md or in a skill? | K41: Ask whether the rule is useful on a turn unrelated to the task. Project-wide facts — stack, architecture, file layout, universal conventions — go in CLAUDE.md, which is always in context. Rules that only apply while doing one class of work — how to add a CLI command, how to write its tests — go in a skill so they cost nothing the rest of the time. | L41: Getting this split right is what keeps both files small and keeps the permanent context clean.
A42: Q38 | B42: 10 | C42: Evaluating Skills Like Software | D42: short | E42: 3 | F42: Outline a minimum credible evaluation for a new skill. | K42: Define should-fire and should-not-fire queries; run each at least three times because triggering is stochastic; write objectively checkable behavioural assertions (file exists at path, all required sections present, steps executed in the specified order); run the same set with the skill disabled as a baseline; record pass rate, tokens and duration as means with standard deviations; hold back part of the set if you are tuning the description; finish with human review and a pass on every model you deploy on. | L42: Trigger reliability, behaviour and cost are three separate failure modes, and only the delta over baseline demonstrates value.
A43: Q39 | B43: 11 | C43: Security, Trust and Governance | D43: short | E43: 2 | F43: What must a pre-install security audit of a third-party skill cover, and what is the top red flag? | K43: The whole folder: SKILL.md end to end, every file in `scripts/` (what it executes, writes and sends), every reference file, and the assets. The top red flag is a skill that fetches an external URL and then acts on what it finds — that delegates the skill's contents to whoever controls the URL, as a mutable, unversioned dependency inside a trusted path. | L43: Reviewing only SKILL.md inspects the least dangerous file in the folder.
A44: Q40 | B44: 05 | C44: Pre-Built Skills, the Marketplace and skill-creator | D44: short | E44: 2 | F44: Why should skill descriptions be slightly 'pushy', and what is the limit of that technique? | K44: Models systematically under-trigger skills, so explicit 'use this whenever the user mentions X, Y or Z' language measurably improves firing. The limit is that no description will fire on a trivial one-step request — the model just answers directly — and over-broad descriptions start hijacking unrelated requests, which is why should-not-fire eval cases matter. | L44: Description tuning is a two-sided problem: under-triggering and over-triggering are both failures.
A45: Q41 | B45: 07 | C45: Skills with the Claude Messages API | D45: short | E45: 2 | F45: List the five parts of a Messages API request that uses a custom skill. | K45: 1) The model. 2) The beta headers (historically skills, code-execution and files-api; the skills header is now optional post-GA). 3) `container={"skills": [...]}` naming each skill by type, skill_id and version. 4) `tools` including the code execution tool. 5) Messages referencing uploaded inputs by file_id via a container_upload block. | L45: Omitting the code execution tool produces a 400 rather than a degraded answer.
A46: Q42 | B46: 02 | C46: Anatomy of a Skill and the Open Standard | D46: short | E46: 1 | F46: Name the three conventional skill subdirectories and what each holds. | K46: `scripts/` — code to execute, where only the output enters context. `references/` — documents read on demand, costing their length at read time. `assets/` — templates, logos, schemas and data files used in output rather than read as instructions. | L46: Each directory maps to a different loading mechanic, so the filing decision is really a token-budgeting decision.
A47: Q43 | B47: 06 | C47: Authoring Practice: Descriptions, Degrees of Freedom, Structure | D47: applied | E47: 3 | F47: A compliance team wants every client report to place the disclaimer on page two, use one specific blue, and follow a fixed section order. A marketing team wants help generating visually varied campaign concepts. How should the degrees-of-freedom dial differ between these two skills, and what does that look like concretely? | K47: Compliance gets low freedom: an explicit, ordered sequence, exact hex values, a fixed section list, a named output template in `assets/`, and explicit statements of when a step may be skipped and why. Deviation is a defect. Marketing gets high freedom: the skill states goals, constraints and a palette range rather than a sequence, and deliberately leaves style, layout and colour selection to the model — with the skill supplying brand guardrails rather than a script. | L47: The dial is set by whether variation is a defect or the point. Getting this backwards produces either non-compliant reports or monotonous creative output.
A48: Q44 | B48: 08 | C48: Skills in Claude Code, and Wiring Them to Subagents | D48: applied | E48: 3 | F48: Interactively testing a CLI is filling your main context with repeated run transcripts. Design a fix using the course's primitives, and state what each piece buys you. | K48: Create a test-generation skill carrying your fixture and assertion conventions, and a review skill carrying the convention checklist. Attach each to its own subagent: the reviewer with read-only tools (Read, Grep, Glob, Bash) so it reports rather than fixes; the test runner additionally with Edit and Write since it must create test files. Dispatch both from the parent, which stays on development and receives only verdicts and diffs. The skills buy consistency of method; the subagents buy context isolation and parallelism; the restricted tool lists buy enforcement. | L48: This is the L6 architecture. The read-only reviewer is the detail people skip, and it is what keeps your true error rate visible.
...

Sheet Flashcards
A1: Flashcards
A2: Prompt on the left, answer on the right. Tag groups cards by theme for targeted drilling.
A4: ID | B4: Module | C4: Module title | D4: Tag | E4: Prompt | F4: Answer
A5: C001 | B5: 00 | C5: Course Map and the One-Sentence Mental Model | D5: core | E5: What is a skill, in one sentence? | F5: A folder of instructions — `SKILL.md` plus optional scripts, reference docs and assets — that gives an agent procedural knowledge on demand.
A6: C002 | B6: 00 | C6: Course Map and the One-Sentence Mental Model | D6: core | E6: Minimum contents of a valid skill | F6: One file: `SKILL.md`, with `name` and `description` in YAML frontmatter, plus a markdown body.
A7: C003 | B7: 00 | C7: Course Map and the One-Sentence Mental Model | D7: core | E7: Two tools an agent must have for skills to work | F7: Filesystem access (read/write files) and a bash-style execution tool.
A8: C004 | B8: 00 | C8: Course Map and the One-Sentence Mental Model | D8: core | E8: The behavioural trigger for writing a skill | F8: You are retyping the same prompt across conversations — the prompt has become a workflow.
A9: C005 | B9: 00 | C9: Course Map and the One-Sentence Mental Model | D9: core | E9: Four harnesses the course covers | F9: Claude.ai/Desktop, the Messages API, Claude Code, the Claude Agent SDK.
A10: C006 | B10: 01 | C10: Why Skills: From Repeated Prompt to Packaged Asset | D10: why | E10: Four costs of the prompt-based workflow that a skill removes | F10: Repetition, reliance on tacit knowledge, context pollution, and no way to share or version it.
A11: C007 | B11: 01 | C11: Why Skills: From Repeated Prompt to Packaged Asset | D11: why | E11: Which part of the marketing workflow became a reference file, and why | F11: Budget reallocation rules — conditional (rarely asked) and bulky (thresholds and a framework). Conditional + bulky = `references/`.
A12: C008 | B12: 01 | C12: Why Skills: From Repeated Prompt to Packaged Asset | D12: why | E12: Skill folder naming rules | F12: Lowercase letters, numbers and hyphens; gerund (`verb+ing`) form reads best; no reserved vendor words such as 'claude' or 'anthropic'.
A13: C009 | B13: 01 | C13: Why Skills: From Repeated Prompt to Packaged Asset | D13: why | E13: How a skill is installed in Claude.ai | F13: Zip the skill folder, then Settings → Capabilities → Skills → Add, and upload the zip.
A14: C010 | B14: 01 | C14: Why Skills: From Repeated Prompt to Packaged Asset | D14: why | E14: What made the Excel report possible without writing spreadsheet code | F14: Claude's built-in Excel document skill — a custom skill produced the analysis, a built-in skill produced the file.
A15: C011 | B15: 01 | C15: Why Skills: From Repeated Prompt to Packaged Asset | D15: why | E15: Does a skill uploaded to Claude.ai work in the API? | F15: No. Claude.ai/Desktop skills are a separate store from the API and Claude Code; install the folder separately in each.
... A102: C098 | B102: 13 | C102: Applying This to Data-Operations Work | D102: applied | E102: Why name the output tree in the skill? | F102: Reproducible paths are what make a run auditable months later.

Sheet Spec Cheat Sheet
A1: Spec Cheat Sheet
A2: Hard limits, directory names, paths and API strings, in module order.
A4: Module | B4: Module title | C4: Fact | D4: Value
A5: 00 | B5: Course Map and the One-Sentence Mental Model | C5: Required files | D5: SKILL.md (1)
A6: 00 | B6: Course Map and the One-Sentence Mental Model | C6: Required frontmatter | D6: name, description
A7: 00 | B7: Course Map and the One-Sentence Mental Model | C7: Runtime floor | D7: filesystem + bash/exec tool
A8: 00 | B8: Course Map and the One-Sentence Mental Model | C8: Course lessons | D8: 8 (intro + 7)
A9: 00 | B9: Course Map and the One-Sentence Mental Model | C9: Harnesses covered | D9: Claude.ai/Desktop, Messages API, Claude Code, Agent SDK
A10: 01 | B10: Why Skills: From Repeated Prompt to Packaged Asset | C10: Naming | D10: lowercase, hyphens, gerund form
A11: 01 | B11: Why Skills: From Repeated Prompt to Packaged Asset | C11: Forbidden in name | D11: 'anthropic', 'claude'
A12: 01 | B12: Why Skills: From Repeated Prompt to Packaged Asset | C12: Folder vs name | D12: must match under the open spec
A13: 01 | B13: Why Skills: From Repeated Prompt to Packaged Asset | C13: Install in Claude.ai | D13: zip folder → Settings → Capabilities → Skills → Add
A14: 01 | B14: Why Skills: From Repeated Prompt to Packaged Asset | C14: Reference path in body | D14: references/<file>.md, relative, one level deep
A15: 02 | B15: Anatomy of a Skill and the Open Standard | C15: name max | D15: 64 chars
... A101: 13 | B101: Applying This to Data-Operations Work | C101: Do not skillify | D101: one-off analysis, unsettled conventions

Sheet Glossary
A1: Glossary
A2: One line per term, written for someone joining the work mid-stream.
A4: Term | B4: Definition
A5: Agent Skills | B5: Open standard, published December 2025, defining a skill as a folder containing SKILL.md plus optional scripts, references and assets.
A6: SKILL.md | B6: The single required file in a skill: YAML frontmatter with name and description, followed by a markdown body of instructions.
A7: Frontmatter | B7: The YAML block at the top of SKILL.md. `name` and `description` required; `license`, `compatibility`, `metadata` and `allowed-tools` optional.
A8: Progressive disclosure | B8: Three-tier loading: metadata always, body on match, bundled resources only when directed. The mechanism that lets a system carry 100+ skills.
A9: Metadata tier | B9: Name + description for every installed skill, ~100 tokens each, permanently in context. The only unavoidable cost of a skill.
A10: references/ | B10: Directory for documents the agent reads on demand. Cost is paid at read time, so it suits conditional and bulky material.
A11: scripts/ | B11: Directory for executable code. Cheapest tier: the source is never tokenised, only the output enters context.
A12: assets/ | B12: Directory for templates, logos, schemas and data files used in output rather than read as instructions.
A13: Degrees of freedom | B13: Design dial for how much latitude a skill grants: low for compliance and exact sequence, high for creative variation.
A14: skill-creator | B14: Anthropic's meta-skill: scaffolds, packages, validates, benchmarks against a baseline and optimises skill descriptions.
A15: Document skills | B15: The built-in docx, pdf, pptx and xlsx skills. Always on in Claude.ai/Desktop; must be installed in Claude Code.
... A28: Trigger rate | B28: How often a skill fires on queries that should fire it. Stochastic, so measured over repeated runs.

Sheet Score Tracker
A1: Score Tracker
A2: Enter 1 for correct or 0 for missed in the Score column only. Everything else is calculated.
A4: ID | B4: Module | C4: Type | D4: Difficulty | E4: Question | F4: Score | H4: Summary
A5: ='Quiz Bank'!A5 -> Q01 | B5: ='Quiz Bank'!B5 -> 02 | C5: ='Quiz Bank'!D5 -> mcq | D5: ='Quiz Bank'!E5 -> 1 | E5: ='Quiz Bank'!F5 -> Which fields are REQUIRED in a skill's YAML frontmatter?
A6: ='Quiz Bank'!A6 -> Q02 | B6: ='Quiz Bank'!B6 -> 02 | C6: ='Quiz Bank'!D6 -> mcq | D6: ='Quiz Bank'!E6 -> 1 | E6: ='Quiz Bank'!F6 -> What is the maximum length of a skill's `name`? | H6: Items in bank | I6: =COUNTA(A5:A69) -> 65
A7: ='Quiz Bank'!A7 -> Q03 | B7: ='Quiz Bank'!B7 -> 03 | C7: ='Quiz Bank'!D7 -> mcq | D7: ='Quiz Bank'!E7 -> 1 | E7: ='Quiz Bank'!F7 -> At session start, what is loaded into context for every installed skill? | H7: Attempted | I7: =COUNT(F5:F69) -> 0
A8: ='Quiz Bank'!A8 -> Q04 | B8: ='Quiz Bank'!B8 -> 03 | C8: ='Quiz Bank'!D8 -> mcq | D8: ='Quiz Bank'!E8 -> 2 | E8: ='Quiz Bank'!F8 -> Why is putting deterministic logic in `scripts/` cheaper than putting it in `references/`? | H8: Correct | I8: =SUM(F5:F69) -> 0
A9: ='Quiz Bank'!A9 -> Q05 | B9: ='Quiz Bank'!B9 -> 05 | C9: ='Quiz Bank'!D9 -> mcq | D9: ='Quiz Bank'!E9 -> 1 | E9: ='Quiz Bank'!F9 -> Which set of skills is built into Claude.ai and cannot be toggled off? | H9: Score | I9: =IFERROR(SUM(F5:F69)/COUNT(F5:F69),0) -> 0
A10: ='Quiz Bank'!A10 -> Q06 | B10: ='Quiz Bank'!B10 -> 05 | C10: ='Quiz Bank'!D10 -> mcq | D10: ='Quiz Bank'!E10 -> 1 | E10: ='Quiz Bank'!F10 -> Which example skill is enabled by default in Claude?
A11: ='Quiz Bank'!A11 -> Q07 | B11: ='Quiz Bank'!B11 -> 07 | C11: ='Quiz Bank'!D11 -> mcq | D11: ='Quiz Bank'!E11 -> 1 | E11: ='Quiz Bank'!F11 -> Which tool is a hard requirement for using skills on the Claude Messages API?
A12: ='Quiz Bank'!A12 -> Q08 | B12: ='Quiz Bank'!B12 -> 07 | C12: ='Quiz Bank'!D12 -> mcq | D12: ='Quiz Bank'!E12 -> 1 | E12: ='Quiz Bank'!F12 -> Where do uploaded custom skills mount inside the API execution container? | H12: By module
A13: ='Quiz Bank'!A13 -> Q09 | B13: ='Quiz Bank'!B13 -> 07 | C13: ='Quiz Bank'!D13 -> mcq | D13: ='Quiz Bank'!E13 -> 2 | E13: ='Quiz Bank'!F13 -> A script inside your skill does `pip install statsmodels` at runtime and fails on the API. Why? | H13: Module | I13: Attempted | J13: Correct | K13: Score
A14: ='Quiz Bank'!A14 -> Q10 | B14: ='Quiz Bank'!B14 -> 08 | C14: ='Quiz Bank'!D14 -> mcq | D14: ='Quiz Bank'!E14 -> 1 | E14: ='Quiz Bank'!F14 -> Where do project-scoped skills live in a Claude Code repository? | H14: 00 | I14: =COUNTIFS($B$5:$B$69,$H14,$F$5:$F$69,"<>") -> 0 | J14: =SUMIFS($F$5:$F$69,$B$5:$B$69,$H14) -> 0 | K14: =IFERROR(SUMIFS($F$5:$F$69,$B$5:$B$69,$H14)/COUNTIFS($B$5:$B$69,$H14,$F$5:$F$69,"<>"),"-") -> -
A15: ='Quiz Bank'!A15 -> Q11 | B15: ='Quiz Bank'!B15 -> 08 | C15: ='Quiz Bank'!D15 -> mcq | D15: ='Quiz Bank'!E15 -> 2 | E15: ='Quiz Bank'!F15 -> You add a new skill folder to `.claude/skills/` and `/skills` does not list it. Most likely cause? | H15: 01 | I15: =COUNTIFS($B$5:$B$69,$H15,$F$5:$F$69,"<>") -> 0 | J15: =SUMIFS($F$5:$F$69,$B$5:$B$69,$H15) -> 0 | K15: =IFERROR(SUMIFS($F$5:$F$69,$B$5:$B$69,$H15)/COUNTIFS($B$5:$B$69,$H15,$F$5:$F$69,"<>"),"-") -> -
A16: ='Quiz Bank'!A16 -> Q12 | B16: ='Quiz Bank'!B16 -> 09 | C16: ='Quiz Bank'!D16 -> mcq | D16: ='Quiz Bank'!E16 -> 2 | E16: ='Quiz Bank'!F16 -> In the Agent SDK you set `allowed_tools=["Skill", "Task", "Bash"]` and your skills still never load. What is missing? | H16: 02 | I16: =COUNTIFS($B$5:$B$69,$H16,$F$5:$F$69,"<>") -> 0 | J16: =SUMIFS($F$5:$F$69,$B$5:$B$69,$H16) -> 0 | K16: =IFERROR(SUMIFS($F$5:$F$69,$B$5:$B$69,$H16)/COUNTIFS($B$5:$B$69,$H16,$F$5:$F$69,"<>"),"-") -> -
A17: ='Quiz Bank'!A17 -> Q13 | B17: ='Quiz Bank'!B17 -> 09 | C17: ='Quiz Bank'!D17 -> mcq | D17: ='Quiz Bank'!E17 -> 1 | E17: ='Quiz Bank'!F17 -> Which tool must be allowed for the main agent to dispatch subagents? | H17: 03 | I17: =COUNTIFS($B$5:$B$69,$H17,$F$5:$F$69,"<>") -> 0 | J17: =SUMIFS($F$5:$F$69,$B$5:$B$69,$H17) -> 0 | K17: =IFERROR(SUMIFS($F$5:$F$69,$B$5:$B$69,$H17)/COUNTIFS($B$5:$B$69,$H17,$F$5:$F$69,"<>"),"-") -> -
A18: ='Quiz Bank'!A18 -> Q14 | B18: ='Quiz Bank'!B18 -> 09 | C18: ='Quiz Bank'!D18 -> mcq | D18: ='Quiz Bank'!E18 -> 1 | E18: ='Quiz Bank'!F18 -> Which tools are permitted by default in the Agent SDK without explicit granting? | H18: 04 | I18: =COUNTIFS($B$5:$B$69,$H18,$F$5:$F$69,"<>") -> 0 | J18: =SUMIFS($F$5:$F$69,$B$5:$B$69,$H18) -> 0 | K18: =IFERROR(SUMIFS($F$5:$F$69,$B$5:$B$69,$H18)/COUNTIFS($B$5:$B$69,$H18,$F$5:$F$69,"<>"),"-") -> -
A19: ='Quiz Bank'!A19 -> Q15 | B19: ='Quiz Bank'!B19 -> 04 | C19: ='Quiz Bank'!D19 -> mcq | D19: ='Quiz Bank'!E19 -> 2 | E19: ='Quiz Bank'!F19 -> Which statement about context cost is correct? | H19: 05 | I19: =COUNTIFS($B$5:$B$69,$H19,$F$5:$F$69,"<>") -> 0 | J19: =SUMIFS($F$5:$F$69,$B$5:$B$69,$H19) -> 0 | K19: =IFERROR(SUMIFS($F$5:$F$69,$B$5:$B$69,$H19)/COUNTIFS($B$5:$B$69,$H19,$F$5:$F$69,"<>"),"-") -> -
A20: ='Quiz Bank'!A20 -> Q16 | B20: ='Quiz Bank'!B20 -> 04 | C20: ='Quiz Bank'!D20 -> mcq | D20: ='Quiz Bank'!E20 -> 2 | E20: ='Quiz Bank'!F20 -> Five teams need the same contract-review methodology. What should you build? | H20: 06 | I20: =COUNTIFS($B$5:$B$69,$H20,$F$5:$F$69,"<>") -> 0 | J20: =SUMIFS($F$5:$F$69,$B$5:$B$69,$H20) -> 0 | K20: =IFERROR(SUMIFS($F$5:$F$69,$B$5:$B$69,$H20)/COUNTIFS($B$5:$B$69,$H20,$F$5:$F$69,"<>"),"-") -> -
A21: ='Quiz Bank'!A21 -> Q17 | B21: ='Quiz Bank'!B21 -> 07 | C21: ='Quiz Bank'!D21 -> mcq | D21: ='Quiz Bank'!E21 -> 1 | E21: ='Quiz Bank'!F21 -> What is the maximum number of skills you can mount in one API container? | H21: 07 | I21: =COUNTIFS($B$5:$B$69,$H21,$F$5:$F$69,"<>") -> 0 | J21: =SUMIFS($F$5:$F$69,$B$5:$B$69,$H21) -> 0 | K21: =IFERROR(SUMIFS($F$5:$F$69,$B$5:$B$69,$H21)/COUNTIFS($B$5:$B$69,$H21,$F$5:$F$69,"<>"),"-") -> -
A22: ='Quiz Bank'!A22 -> Q18 | B22: ='Quiz Bank'!B22 -> 06 | C22: ='Quiz Bank'!D22 -> mcq | D22: ='Quiz Bank'!E22 -> 2 | E22: ='Quiz Bank'!F22 -> Your skill supports markdown and LaTeX output. Where should the two templates live? | H22: 08 | I22: =COUNTIFS($B$5:$B$69,$H22,$F$5:$F$69,"<>") -> 0 | J22: =SUMIFS($F$5:$F$69,$B$5:$B$69,$H22) -> 0 | K22: =IFERROR(SUMIFS($F$5:$F$69,$B$5:$B$69,$H22)/COUNTIFS($B$5:$B$69,$H22,$F$5:$F$69,"<>"),"-") -> -
A23: ='Quiz Bank'!A23 -> Q19 | B23: ='Quiz Bank'!B23 -> 12 | C23: ='Quiz Bank'!D23 -> mcq | D23: ='Quiz Bank'!E23 -> 2 | E23: ='Quiz Bank'!F23 -> You want one skill folder to behave identically in Claude Code, Codex and Cursor. What do you restrict yourself to? | H23: 09 | I23: =COUNTIFS($B$5:$B$69,$H23,$F$5:$F$69,"<>") -> 0 | J23: =SUMIFS($F$5:$F$69,$B$5:$B$69,$H23) -> 0 | K23: =IFERROR(SUMIFS($F$5:$F$69,$B$5:$B$69,$H23)/COUNTIFS($B$5:$B$69,$H23,$F$5:$F$69,"<>"),"-") -> -
A24: ='Quiz Bank'!A24 -> Q20 | B24: ='Quiz Bank'!B24 -> 10 | C24: ='Quiz Bank'!D24 -> mcq | D24: ='Quiz Bank'!E24 -> 3 | E24: ='Quiz Bank'!F24 -> Your skill scores 9/10 on your eval set. What does that alone tell you about the skill's value? | H24: 10 | I24: =COUNTIFS($B$5:$B$69,$H24,$F$5:$F$69,"<>") -> 0 | J24: =SUMIFS($F$5:$F$69,$B$5:$B$69,$H24) -> 0 | K24: =IFERROR(SUMIFS($F$5:$F$69,$B$5:$B$69,$H24)/COUNTIFS($B$5:$B$69,$H24,$F$5:$F$69,"<>"),"-") -> -
A25: ='Quiz Bank'!A25 -> Q21 | B25: ='Quiz Bank'!B25 -> 01 | C25: ='Quiz Bank'!D25 -> tf | D25: ='Quiz Bank'!E25 -> 1 | E25: ='Quiz Bank'!F25 -> A skill uploaded in Claude.ai is automatically available through the Claude API. | H25: 11 | I25: =COUNTIFS($B$5:$B$69,$H25,$F$5:$F$69,"<>") -> 0 | J25: =SUMIFS($F$5:$F$69,$B$5:$B$69,$H25) -> 0 | K25: =IFERROR(SUMIFS($F$5:$F$69,$B$5:$B$69,$H25)/COUNTIFS($B$5:$B$69,$H25,$F$5:$F$69,"<>"),"-") -> -
... A27: ='Quiz Bank'!A27 -> Q23 | B27: ='Quiz Bank'!B27 -> 03 | C27: ='Quiz Bank'!D27 -> tf | D27: ='Quiz Bank'!E27 -> 2 | E27: ='Quiz Bank'!F27 -> Progressive disclosure applies inside a dispatched subagent exactly as it does in the main agent. | H27: 13 | I27: =COUNTIFS($B$5:$B$69,$H27,$F$5:$F$69,"<>") -> 0 | J27: =SUMIFS($F$5:$F$69,$B$5:$B$69,$H27) -> 0 | K27: =IFERROR(SUMIFS($F$5:$F$69,$B$5:$B$69,$H27)/COUNTIFS($B$5:$B$69,$H27,$F$5:$F$69,"<>"),"-") -> -
A28: ='Quiz Bank'!A28 -> Q24 | B28: ='Quiz Bank'!B28 -> 11 | C28: ='Quiz Bank'!D28 -> tf | D28: ='Quiz Bank'!E28 -> 2 | E28: ='Quiz Bank'!F28 -> Instructions in a SKILL.md body can prevent an agent from writing files. | H28: Total | I28: =COUNT($F$5:$F$69) -> 0 | J28: =SUM($F$5:$F$69) -> 0 | K28: =IFERROR(SUM($F$5:$F$69)/COUNT($F$5:$F$69),"-") -> -
A29: ='Quiz Bank'!A29 -> Q25 | B29: ='Quiz Bank'!B29 -> 02 | C29: ='Quiz Bank'!D29 -> tf | D29: ='Quiz Bank'!E29 -> 1 | E29: ='Quiz Bank'!F29 -> Unknown top-level frontmatter fields cause a skill to fail loading.
A30: ='Quiz Bank'!A30 -> Q26 | B30: ='Quiz Bank'!B30 -> 05 | C30: ='Quiz Bank'!D30 -> tf | D30: ='Quiz Bank'!E30 -> 1 | E30: ='Quiz Bank'!F30 -> Claude Code ships with the document skills already installed. | H30: By item type
A31: ='Quiz Bank'!A31 -> Q27 | B31: ='Quiz Bank'!B31 -> 05 | C31: ='Quiz Bank'!D31 -> tf | D31: ='Quiz Bank'!E31 -> 2 | E31: ='Quiz Bank'!F31 -> A perfectly matching description guarantees the skill will fire. | H31: Type | I31: Attempted | J31: Correct | K31: Score
A32: ='Quiz Bank'!A32 -> Q28 | B32: ='Quiz Bank'!B32 -> 07 | C32: ='Quiz Bank'!D32 -> tf | D32: ='Quiz Bank'!E32 -> 2 | E32: ='Quiz Bank'!F32 -> Files uploaded through the Files API expire automatically after a short retention window. | H32: mcq | I32: =COUNTIFS($C$5:$C$69,$H32,$F$5:$F$69,"<>") -> 0 | J32: =SUMIFS($F$5:$F$69,$C$5:$C$69,$H32) -> 0 | K32: =IFERROR(SUMIFS($F$5:$F$69,$C$5:$C$69,$H32)/COUNTIFS($C$5:$C$69,$H32,$F$5:$F$69,"<>"),"-") -> -
A33: ='Quiz Bank'!A33 -> Q29 | B33: ='Quiz Bank'!B33 -> 04 | C33: ='Quiz Bank'!D33 -> tf | D33: ='Quiz Bank'!E33 -> 2 | E33: ='Quiz Bank'!F33 -> A subagent can spawn its own subagents to parallelise further. | H33: tf | I33: =COUNTIFS($C$5:$C$69,$H33,$F$5:$F$69,"<>") -> 0 | J33: =SUMIFS($F$5:$F$69,$C$5:$C$69,$H33) -> 0 | K33: =IFERROR(SUMIFS($F$5:$F$69,$C$5:$C$69,$H33)/COUNTIFS($C$5:$C$69,$H33,$F$5:$F$69,"<>"),"-") -> -
A34: ='Quiz Bank'!A34 -> Q30 | B34: ='Quiz Bank'!B34 -> 09 | C34: ='Quiz Bank'!D34 -> tf | D34: ='Quiz Bank'!E34 -> 2 | E34: ='Quiz Bank'!F34 -> Listing a tool in a subagent's own tool list is sufficient for that subagent to use it. | H34: short | I34: =COUNTIFS($C$5:$C$69,$H34,$F$5:$F$69,"<>") -> 0 | J34: =SUMIFS($F$5:$F$69,$C$5:$C$69,$H34) -> 0 | K34: =IFERROR(SUMIFS($F$5:$F$69,$C$5:$C$69,$H34)/COUNTIFS($C$5:$C$69,$H34,$F$5:$F$69,"<>"),"-") -> -
A35: ='Quiz Bank'!A35 -> Q31 | B35: ='Quiz Bank'!B35 -> 02 | C35: ='Quiz Bank'!D35 -> tf | D35: ='Quiz Bank'!E35 -> 1 | E35: ='Quiz Bank'!F35 -> The folder name and the frontmatter `name` must match under the open specification. | H35: applied | I35: =COUNTIFS($C$5:$C$69,$H35,$F$5:$F$69,"<>") -> 0 | J35: =SUMIFS($F$5:$F$69,$C$5:$C$69,$H35) -> 0 | K35: =IFERROR(SUMIFS($F$5:$F$69,$C$5:$C$69,$H35)/COUNTIFS($C$5:$C$69,$H35,$F$5:$F$69,"<>"),"-") -> -
A36: ='Quiz Bank'!A36 -> Q32 | B36: ='Quiz Bank'!B36 -> 12 | C36: ='Quiz Bank'!D36 -> tf | D36: ='Quiz Bank'!E36 -> 2 | E36: ='Quiz Bank'!F36 -> `allowed-tools` is a reliable cross-host security control.
A37: ='Quiz Bank'!A37 -> Q33 | B37: ='Quiz Bank'!B37 -> 03 | C37: ='Quiz Bank'!D37 -> short | D37: ='Quiz Bank'!E37 -> 1 | E37: ='Quiz Bank'!F37 -> Name the three tiers of progressive disclosure and what loads at each.
A38: ='Quiz Bank'!A38 -> Q34 | B38: ='Quiz Bank'!B38 -> 01 | C38: ='Quiz Bank'!D38 -> short | D38: ='Quiz Bank'!E38 -> 2 | E38: ='Quiz Bank'!F38 -> Give the signature of content that belongs in `references/` rather than in the SKILL.md body, and an example from the course. | H38: Score is correct divided by attempted, so blanks do not count against the learner.
A39: ='Quiz Bank'!A39 -> Q35 | B39: ='Quiz Bank'!B39 -> 06 | C39: ='Quiz Bank'!D39 -> short | D39: ='Quiz Bank'!E39 -> 2 | E39: ='Quiz Bank'!F39 -> Describe the three-part architecture used by the time-series skill and why each part sits where it does.
A40: ='Quiz Bank'!A40 -> Q36 | B40: ='Quiz Bank'!B40 -> 04 | C40: ='Quiz Bank'!D40 -> short | D40: ='Quiz Bank'!E40 -> 2 | E40: ='Quiz Bank'!F40 -> Explain the difference between MCP and a skill using one concrete example.
A41: ='Quiz Bank'!A41 -> Q37 | B41: ='Quiz Bank'!B41 -> 08 | C41: ='Quiz Bank'!D41 -> short | D41: ='Quiz Bank'!E41 -> 2 | E41: ='Quiz Bank'!F41 -> How do you decide whether a convention belongs in CLAUDE.md or in a skill?
A42: ='Quiz Bank'!A42 -> Q38 | B42: ='Quiz Bank'!B42 -> 10 | C42: ='Quiz Bank'!D42 -> short | D42: ='Quiz Bank'!E42 -> 3 | E42: ='Quiz Bank'!F42 -> Outline a minimum credible evaluation for a new skill.
...
